Workbook

Sheet BURNER STATUS
C4: Reformer-A WALL
C5: 1 | D5: 2 | E5: 3 | F5: 4 | G5: 5 | H5: 6 | I5: 7 | J5: 8 | K5: 9 | L5: 10 | M5: 11 | N5: 12 | O5: 13 | P5: 14 | Q5: 15 | R5: OFF GAS BURNER | S5: NG BURNER | T5: TOTAL | U5: AB total | W5: OFF Gas Diff | X5: NG Diff | Y5: DIFFERENCE
B6: ROW 1 | C6: N | D6: O | E6: N | F6: O | G6: C | H6: C | I6: C | J6: C | K6: N | L6: N | M6: N | N6: C | O6: O | P6: C | Q6: C | R6: =COUNTIF(C6:Q6,"O")+COUNTIF(C6:Q6,"B") -> 3 | S6: =COUNTIF(C6:Q6,"N")+COUNTIF(C6:Q6,"B") -> 5 | T6: =S6+R6 -> 8 | U6: =T6+T14 -> 19 | W6: =R6+R14-R22-R30 -> 8 | X6: =S6+S14-S22-S30 -> 6 | Y6: =U6-U22 -> 14
B7: ROW 2 | C7: B | D7: O | E7: N | F7: N | G7: C | H7: O | I7: C | J7: C | K7: N | L7: B | M7: O | N7: O | O7: N | P7: O | Q7: B | R7: =COUNTIF(C7:Q7,"O")+COUNTIF(C7:Q7,"B") -> 8 | S7: =COUNTIF(C7:Q7,"N")+COUNTIF(C7:Q7,"B") -> 7 | T7: =S7+R7 -> 15 | U7: =T7+T15 -> 35 | W7: =R7+R15-R23-R31 -> -2 | X7: =S7+S15-S23-S31 -> -13 | Y7: =U7-U23 -> -15 | AA7: B | AB7: OFF GAS AND NG BURNER
B8: ROW 3 | C8: O | D8: O | E8: O | F8: N | G8: O | H8: O | I8: N | J8: N | K8: B | L8: K | M8: C | N8: C | O8: N | P8: O | Q8: C | R8: =COUNTIF(C8:Q8,"O")+COUNTIF(C8:Q8,"B") -> 7 | S8: =COUNTIF(C8:Q8,"N")+COUNTIF(C8:Q8,"B") -> 5 | T8: =S8+R8 -> 12 | U8: =T8+T16 -> 25 | W8: =R8+R16-R24-R32 -> -11 | X8: =S8+S16-S24-S32 -> 1 | Y8: =U8-U24 -> -10
B9: ROW 4 | C9: C | D9: C | E9: N | F9: B | G9: B | H9: B | I9: O | J9: C | K9: C | L9: O | M9: C | N9: O | O9: O | P9: C | Q9: C | R9: =COUNTIF(C9:Q9,"O")+COUNTIF(C9:Q9,"B") -> 7 | S9: =COUNTIF(C9:Q9,"N")+COUNTIF(C9:Q9,"B") -> 4 | T9: =S9+R9 -> 11 | U9: =T9+T17 -> 24 | W9: =R9+R17-R25-R33 -> 1 | X9: =S9+S17-S25-S33 -> 4 | Y9: =U9-U25 -> 5 | AA9: O | AB9: OFF GAS BURNER
B10: ROW 5 | C10: B | D10: N | E10: B | F10: C | G10: O | H10: O | I10: B | J10: B | K10: B | L10: N | M10: C | N10: O | O10: N | P10: O | Q10: B | R10: =COUNTIF(C10:Q10,"O")+COUNTIF(C10:Q10,"B") -> 10 | S10: =COUNTIF(C10:Q10,"N")+COUNTIF(C10:Q10,"B") -> 9 | T10: =S10+R10 -> 19 | U10: =T10+T18 -> 40 | W10: =R10+R18-R26-R34 -> -5 | X10: =S10+S18-S26-S34 -> 7 | Y10: =U10-U26 -> 2
B11: ROW 6 | C11: O | D11: C | E11: O | F11: B | G11: N | H11: B | I11: N | J11: N | K11: C | L11: N | M11: C | N11: N | O11: C | P11: B | Q11: N | R11: =COUNTIF(C11:Q11,"O")+COUNTIF(C11:Q11,"B") -> 5 | S11: =COUNTIF(C11:Q11,"N")+COUNTIF(C11:Q11,"B") -> 9 | T11: =S11+R11 -> 14 | U11: =T11+T19 -> 31 | W11: =R11+R19-R27-R35 -> -14 | X11: =S11+S19-S27-S35 -> -2 | Y11: =U11-U27 -> -16 | AA11: N | AB11: NG BURNER
R12: =SUM(R6:R11) -> 40 | S12: =SUM(S6:S11) -> 39 | U12: =SUM(U6:U11) -> 174
C13: Reformer-B WALL | AA13: C | AB13: BOTH BURNER CLOSED
B14: ROW 1 | C14: O | D14: C | E14: O | F14: O | G14: O | H14: C | I14: O | J14: C | K14: C | L14: N | M14: B | N14: O | O14: N | P14: C | Q14: N | R14: =COUNTIF(C14:Q14,"O")+COUNTIF(C14:Q14,"B") -> 7 | S14: =COUNTIF(C14:Q14,"N")+COUNTIF(C14:Q14,"B") -> 4 | T14: =S14+R14 -> 11
B15: ROW 2 | C15: B | D15: B | E15: O | F15: B | G15: N | H15: N | I15: O | J15: C | K15: B | L15: C | M15: B | N15: B | O15: O | P15: B | Q15: O | R15: =COUNTIF(C15:Q15,"O")+COUNTIF(C15:Q15,"B") -> 11 | S15: =COUNTIF(C15:Q15,"N")+COUNTIF(C15:Q15,"B") -> 9 | T15: =S15+R15 -> 20
B16: ROW 3 | C16: O | D16: O | E16: O | F16: N | G16: N | H16: N | I16: O | J16: C | K16: O | L16: N | M16: O | N16: N | O16: C | P16: N | Q16: N | R16: =COUNTIF(C16:Q16,"O")+COUNTIF(C16:Q16,"B") -> 6 | S16: =COUNTIF(C16:Q16,"N")+COUNTIF(C16:Q16,"B") -> 7 | T16: =S16+R16 -> 13
B17: ROW 4 | C17: N | D17: C | E17: N | F17: N | G17: N | H17: O | I17: O | J17: O | K17: C | L17: N | M17: C | N17: N | O17: N | P17: B | Q17: O | R17: =COUNTIF(C17:Q17,"O")+COUNTIF(C17:Q17,"B") -> 5 | S17: =COUNTIF(C17:Q17,"N")+COUNTIF(C17:Q17,"B") -> 8 | T17: =S17+R17 -> 13
B18: ROW 5 | C18: N | D18: O | E18: N | F18: N | G18: C | H18: O | I18: N | J18: N | K18: B | L18: B | M18: B | N18: B | O18: B | P18: B | Q18: B | R18: =COUNTIF(C18:Q18,"O")+COUNTIF(C18:Q18,"B") -> 9 | S18: =COUNTIF(C18:Q18,"N")+COUNTIF(C18:Q18,"B") -> 12 | T18: =S18+R18 -> 21
B19: ROW 6 | C19: B | D19: B | E19: N | F19: N | G19: O | H19: C | I19: N | J19: B | K19: N | L19: B | M19: N | N19: O | O19: N | P19: N | Q19: C | R19: =COUNTIF(C19:Q19,"O")+COUNTIF(C19:Q19,"B") -> 6 | S19: =COUNTIF(C19:Q19,"N")+COUNTIF(C19:Q19,"B") -> 11 | T19: =S19+R19 -> 17
R20: =SUM(R14:R19) -> 44 | S20: =SUM(S14:S19) -> 51
C21: Reformer-C WALL | U21: CD total
B22: ROW 1 | C22: C | D22: C | E22: N | F22: C | G22: C | H22: C | I22: C | J22: C | K22: C | L22: C | M22: C | N22: C | O22: C | P22: C | Q22: C | R22: =COUNTIF(C22:Q22,"O")+COUNTIF(C22:Q22,"B") -> 0 | S22: =COUNTIF(C22:Q22,"N")+COUNTIF(C22:Q22,"B") -> 1 | T22: =S22+R22 -> 1 | U22: =T22+T30 -> 5 | W22: =-W6 -> -8 | X22: =-X6 -> -6 | Y22: =U22-U6 -> -14
B23: ROW 2 | C23: B | D23: B | E23: O | F23: N | G23: B | H23: B | I23: B | J23: B | K23: B | L23: N | M23: B | N23: N | O23: B | P23: B | Q23: N | R23: =COUNTIF(C23:Q23,"O")+COUNTIF(C23:Q23,"B") -> 11 | S23: =COUNTIF(C23:Q23,"N")+COUNTIF(C23:Q23,"B") -> 14 | T23: =S23+R23 -> 25 | U23: =T23+T31 -> 50 | W23: =-W7 -> 2 | X23: =-X7 -> 13 | Y23: =U23-U7 -> 15
B24: ROW 3 | C24: B | D24: B | E24: O | F24: B | G24: O | H24: O | I24: O | J24: B | K24: B | L24: C | M24: O | N24: O | O24: O | P24: O | Q24: B | R24: =COUNTIF(C24:Q24,"O")+COUNTIF(C24:Q24,"B") -> 14 | S24: =COUNTIF(C24:Q24,"N")+COUNTIF(C24:Q24,"B") -> 6 | T24: =S24+R24 -> 20 | U24: =T24+T32 -> 35 | W24: =-W8 -> 11 | X24: =-X8 -> -1 | Y24: =U24-U8 -> 10
B25: ROW 4 | C25: C | D25: O | E25: C | F25: B | G25: N | H25: C | I25: B | J25: O | K25: N | L25: C | M25: C | N25: N | O25: C | P25: N | Q25: N | R25: =COUNTIF(C25:Q25,"O")+COUNTIF(C25:Q25,"B") -> 4 | S25: =COUNTIF(C25:Q25,"N")+COUNTIF(C25:Q25,"B") -> 7 | T25: =S25+R25 -> 11 | U25: =T25+T33 -> 19 | W25: =-W9 -> -1 | X25: =-X9 -> -4 | Y25: =U25-U9 -> -5
B26: ROW 5 | C26: B | D26: B | E26: B | F26: B | G26: B | H26: B | I26: C | J26: O | K26: O | L26: O | M26: O | N26: B | O26: B | P26: B | Q26: B | R26: =COUNTIF(C26:Q26,"O")+COUNTIF(C26:Q26,"B") -> 14 | S26: =COUNTIF(C26:Q26,"N")+COUNTIF(C26:Q26,"B") -> 10 | T26: =S26+R26 -> 24 | U26: =T26+T34 -> 38 | W26: =-W10 -> 5 | X26: =-X10 -> -7 | Y26: =U26-U10 -> -2
B27: ROW 6 | C27: N | D27: N | E27: B | F27: B | G27: B | H27: B | I27: B | J27: B | K27: O | L27: B | M27: N | N27: B | O27: B | P27: B | Q27: B | R27: =COUNTIF(C27:Q27,"O")+COUNTIF(C27:Q27,"B") -> 12 | S27: =COUNTIF(C27:Q27,"N")+COUNTIF(C27:Q27,"B") -> 14 | T27: =S27+R27 -> 26 | U27: =T27+T35 -> 47 | W27: =-W11 -> 14 | X27: =-X11 -> 2 | Y27: =U27-U11 -> 16
R28: =SUM(R22:R27) -> 55 | S28: =SUM(S22:S27) -> 52 | U28: =SUM(U22:U27) -> 194
C29: Reformer-D WALL
B30: ROW 1 | C30: O | D30: O | E30: N | F30: N | G30: C | H30: C | I30: C | J30: C | K30: C | L30: C | M30: C | N30: C | O30: C | P30: C | Q30: C | R30: =COUNTIF(C30:Q30,"O")+COUNTIF(C30:Q30,"B") -> 2 | S30: =COUNTIF(C30:Q30,"N")+COUNTIF(C30:Q30,"B") -> 2 | T30: =S30+R30 -> 4
B31: ROW 2 | C31: B | D31: B | E31: B | F31: N | G31: N | H31: B | I31: B | J31: B | K31: B | L31: B | M31: N | N31: B | O31: N | P31: B | Q31: N | R31: =COUNTIF(C31:Q31,"O")+COUNTIF(C31:Q31,"B") -> 10 | S31: =COUNTIF(C31:Q31,"N")+COUNTIF(C31:Q31,"B") -> 15 | T31: =S31+R31 -> 25
B32: ROW 3 | C32: B | D32: O | E32: C | F32: O | G32: O | H32: B | I32: B | J32: O | K32: B | L32: C | M32: O | N32: C | O32: O | P32: C | Q32: N | R32: =COUNTIF(C32:Q32,"O")+COUNTIF(C32:Q32,"B") -> 10 | S32: =COUNTIF(C32:Q32,"N")+COUNTIF(C32:Q32,"B") -> 5 | T32: =S32+R32 -> 15
B33: ROW 4 | C33: C | D33: O | E33: C | F33: O | G33: C | H33: O | I33: B | J33: O | K33: C | L33: O | M33: C | N33: C | O33: O | P33: C | Q33: C | R33: =COUNTIF(C33:Q33,"O")+COUNTIF(C33:Q33,"B") -> 7 | S33: =COUNTIF(C33:Q33,"N")+COUNTIF(C33:Q33,"B") -> 1 | T33: =S33+R33 -> 8
B34: ROW 5 | C34: O | D34: N | E34: B | F34: N | G34: C | H34: C | I34: O | J34: C | K34: O | L34: O | M34: O | N34: O | O34: B | P34: O | Q34: O | R34: =COUNTIF(C34:Q34,"O")+COUNTIF(C34:Q34,"B") -> 10 | S34: =COUNTIF(C34:Q34,"N")+COUNTIF(C34:Q34,"B") -> 4 | T34: =S34+R34 -> 14
B35: ROW 6 | C35: B | D35: B | E35: C | F35: B | G35: O | H35: B | I35: B | J35: B | K35: B | L35: O | M35: B | N35: O | O35: C | P35: O | Q35: O | R35: =COUNTIF(C35:Q35,"O")+COUNTIF(C35:Q35,"B") -> 13 | S35: =COUNTIF(C35:Q35,"N")+COUNTIF(C35:Q35,"B") -> 8 | T35: =S35+R35 -> 21
R36: =SUM(R30:R35) -> 52 | S36: =SUM(S30:S35) -> 35
P37: TOTAL | R37: =SUM(R6:R11,R14:R19,R22:R27,R30:R35) -> 191 | S37: =SUM(S6:S11,S14:S19,S22:S27,S30:S35) -> 177

Sheet Sheet1
C4: Reformer-A WALL
C5: 1 | D5: 2 | E5: 3 | F5: 4 | G5: 5 | H5: 6 | I5: 7 | J5: 8 | K5: 9 | L5: 10 | M5: 11 | N5: 12 | O5: 13 | P5: 14 | Q5: 15 | R5: OFF GAS BURNER | S5: NG BURNER | T5: TOTAL | U5: AB total | W5: OFF Gas Diff | X5: NG Diff | Y5: DIFFERENCE
B6: ROW 1 | C6: ='BURNER STATUS'!C6 -> N | D6: ='BURNER STATUS'!D6 -> O | E6: ='BURNER STATUS'!E6 -> N | F6: ='BURNER STATUS'!F6 -> O | G6: ='BURNER STATUS'!G6 -> C | H6: ='BURNER STATUS'!H6 -> C | I6: ='BURNER STATUS'!I6 -> C | J6: ='BURNER STATUS'!J6 -> C | ... Q6: ='BURNER STATUS'!Q6 -> C | R6: =COUNTIF(C6:Q6,"O")+COUNTIF(C6:Q6,"B") -> 3 | S6: =COUNTIF(C6:Q6,"N")+COUNTIF(C6:Q6,"B") -> 5 | T6: =S6+R6 -> 8 | U6: =T6+T20 -> 19 | W6: =R6+R20-R34-R48 -> 8 | X6: =S6+S20-S34-S48 -> 6 | Y6: =U6-U34 -> 14
B7: AIR REGISTER POSITION | C7: ='BURNER STATUS'!#REF! -> #REF! | D7: ='BURNER STATUS'!#REF! -> #REF! | E7: ='BURNER STATUS'!#REF! -> #REF! | F7: ='BURNER STATUS'!#REF! -> #REF! | G7: ='BURNER STATUS'!#REF! -> #REF! | H7: ='BURNER STATUS'!#REF! -> #REF! | I7: ='BURNER STATUS'!#REF! -> #REF! | J7: ='BURNER STATUS'!#REF! -> #REF! | ... Q7: ='BURNER STATUS'!#REF! -> #REF!
B8: ROW 2 | C8: ='BURNER STATUS'!C7 -> B | D8: ='BURNER STATUS'!D7 -> O | E8: ='BURNER STATUS'!E7 -> N | F8: ='BURNER STATUS'!F7 -> N | G8: ='BURNER STATUS'!G7 -> C | H8: ='BURNER STATUS'!H7 -> O | I8: ='BURNER STATUS'!I7 -> C | J8: ='BURNER STATUS'!J7 -> C | ... Q8: ='BURNER STATUS'!Q7 -> B | R8: =COUNTIF(C8:Q8,"O")+COUNTIF(C8:Q8,"B") -> 8 | S8: =COUNTIF(C8:Q8,"N")+COUNTIF(C8:Q8,"B") -> 7 | T8: =S8+R8 -> 15 | U8: =T8+T22 -> 35 | W8: =R8+R22-R36-R50 -> -2 | X8: =S8+S22-S36-S50 -> -13 | Y8: =U8-U36 -> -15 | AA8: B | AB8: OFF GAS AND NG BURNER
B9: AIR REGISTER POSITION | C9: ='BURNER STATUS'!#REF! -> #REF! | D9: ='BURNER STATUS'!#REF! -> #REF! | E9: ='BURNER STATUS'!#REF! -> #REF! | F9: ='BURNER STATUS'!#REF! -> #REF! | G9: ='BURNER STATUS'!#REF! -> #REF! | H9: ='BURNER STATUS'!#REF! -> #REF! | I9: ='BURNER STATUS'!#REF! -> #REF! | J9: ='BURNER STATUS'!#REF! -> #REF! | ... Q9: ='BURNER STATUS'!#REF! -> #REF!
B10: ROW 3 | C10: ='BURNER STATUS'!C8 -> O | D10: ='BURNER STATUS'!D8 -> O | E10: ='BURNER STATUS'!E8 -> O | F10: ='BURNER STATUS'!F8 -> N | G10: ='BURNER STATUS'!G8 -> O | H10: ='BURNER STATUS'!H8 -> O | I10: ='BURNER STATUS'!I8 -> N | J10: ='BURNER STATUS'!J8 -> N | ... Q10: ='BURNER STATUS'!Q8 -> C | R10: =COUNTIF(C10:Q10,"O")+COUNTIF(C10:Q10,"B") -> 7 | S10: =COUNTIF(C10:Q10,"N")+COUNTIF(C10:Q10,"B") -> 5 | T10: =S10+R10 -> 12 | U10: =T10+T24 -> 25 | W10: =R10+R24-R38-R52 -> -11 | X10: =S10+S24-S38-S52 -> 1 | Y10: =U10-U38 -> -10
B11: AIR REGISTER POSITION | C11: ='BURNER STATUS'!#REF! -> #REF! | D11: ='BURNER STATUS'!#REF! -> #REF! | E11: ='BURNER STATUS'!#REF! -> #REF! | F11: ='BURNER STATUS'!#REF! -> #REF! | G11: ='BURNER STATUS'!#REF! -> #REF! | H11: ='BURNER STATUS'!#REF! -> #REF! | I11: ='BURNER STATUS'!#REF! -> #REF! | J11: ='BURNER STATUS'!#REF! -> #REF! | ... Q11: ='BURNER STATUS'!#REF! -> #REF!
B12: ROW 4 | C12: ='BURNER STATUS'!C9 -> C | D12: ='BURNER STATUS'!D9 -> C | E12: ='BURNER STATUS'!E9 -> N | F12: ='BURNER STATUS'!F9 -> B | G12: ='BURNER STATUS'!G9 -> B | H12: ='BURNER STATUS'!H9 -> B | I12: ='BURNER STATUS'!I9 -> O | J12: ='BURNER STATUS'!J9 -> C | ... Q12: ='BURNER STATUS'!Q9 -> C | R12: =COUNTIF(C12:Q12,"O")+COUNTIF(C12:Q12,"B") -> 7 | S12: =COUNTIF(C12:Q12,"N")+COUNTIF(C12:Q12,"B") -> 4 | T12: =S12+R12 -> 11 | U12: =T12+T26 -> 24 | W12: =R12+R26-R40-R54 -> 1 | X12: =S12+S26-S40-S54 -> 4 | Y12: =U12-U40 -> 5 | AA12: O | AB12: OFF GAS BURNER
B13: AIR REGISTER POSITION | C13: ='BURNER STATUS'!#REF! -> #REF! | D13: ='BURNER STATUS'!#REF! -> #REF! | E13: ='BURNER STATUS'!#REF! -> #REF! | F13: ='BURNER STATUS'!#REF! -> #REF! | G13: ='BURNER STATUS'!#REF! -> #REF! | H13: ='BURNER STATUS'!#REF! -> #REF! | I13: ='BURNER STATUS'!#REF! -> #REF! | J13: ='BURNER STATUS'!#REF! -> #REF! | ... Q13: ='BURNER STATUS'!#REF! -> #REF!
B14: ROW 5 | C14: ='BURNER STATUS'!C10 -> B | D14: ='BURNER STATUS'!D10 -> N | E14: ='BURNER STATUS'!E10 -> B | F14: ='BURNER STATUS'!F10 -> C | G14: ='BURNER STATUS'!G10 -> O | H14: ='BURNER STATUS'!H10 -> O | I14: ='BURNER STATUS'!I10 -> B | J14: ='BURNER STATUS'!J10 -> B | ... Q14: ='BURNER STATUS'!Q10 -> B | R14: =COUNTIF(C14:Q14,"O")+COUNTIF(C14:Q14,"B") -> 10 | S14: =COUNTIF(C14:Q14,"N")+COUNTIF(C14:Q14,"B") -> 9 | T14: =S14+R14 -> 19 | U14: =T14+T28 -> 40 | W14: =R14+R28-R42-R56 -> -5 | X14: =S14+S28-S42-S56 -> 7 | Y14: =U14-U42 -> 2
B15: AIR REGISTER POSITION | C15: ='BURNER STATUS'!#REF! -> #REF! | D15: ='BURNER STATUS'!#REF! -> #REF! | E15: ='BURNER STATUS'!#REF! -> #REF! | F15: ='BURNER STATUS'!#REF! -> #REF! | G15: ='BURNER STATUS'!#REF! -> #REF! | H15: ='BURNER STATUS'!#REF! -> #REF! | I15: ='BURNER STATUS'!#REF! -> #REF! | J15: ='BURNER STATUS'!#REF! -> #REF! | ... Q15: ='BURNER STATUS'!#REF! -> #REF!
B16: ROW 6 | C16: ='BURNER STATUS'!C11 -> O | D16: ='BURNER STATUS'!D11 -> C | E16: ='BURNER STATUS'!E11 -> O | F16: ='BURNER STATUS'!F11 -> B | G16: ='BURNER STATUS'!G11 -> N | H16: ='BURNER STATUS'!H11 -> B | I16: ='BURNER STATUS'!I11 -> N | J16: ='BURNER STATUS'!J11 -> N | ... Q16: ='BURNER STATUS'!Q11 -> N | R16: =COUNTIF(C16:Q16,"O")+COUNTIF(C16:Q16,"B") -> 5 | S16: =COUNTIF(C16:Q16,"N")+COUNTIF(C16:Q16,"B") -> 9 | T16: =S16+R16 -> 14 | U16: =T16+T30 -> 31 | W16: =R16+R30-R44-R58 -> -14 | X16: =S16+S30-S44-S58 -> -2 | Y16: =U16-U44 -> -16 | AA16: N | AB16: NG BURNER
B17: AIR REGISTER POSITION | C17: ='BURNER STATUS'!#REF! -> #REF! | D17: ='BURNER STATUS'!#REF! -> #REF! | E17: ='BURNER STATUS'!#REF! -> #REF! | F17: ='BURNER STATUS'!#REF! -> #REF! | G17: ='BURNER STATUS'!#REF! -> #REF! | H17: ='BURNER STATUS'!#REF! -> #REF! | I17: ='BURNER STATUS'!#REF! -> #REF! | J17: ='BURNER STATUS'!#REF! -> #REF! | ... Q17: ='BURNER STATUS'!#REF! -> #REF!
R18: =SUM(R6:R16) -> 40 | S18: =SUM(S6:S16) -> 39 | U18: =SUM(U6:U16) -> 174
C19: Reformer-B WALL | AA19: C | AB19: BOTH BURNER CLOSED
B20: ROW 1 | C20: ='BURNER STATUS'!C14 -> O | D20: ='BURNER STATUS'!D14 -> C | E20: ='BURNER STATUS'!E14 -> O | F20: ='BURNER STATUS'!F14 -> O | G20: ='BURNER STATUS'!G14 -> O | H20: ='BURNER STATUS'!H14 -> C | I20: ='BURNER STATUS'!I14 -> O | J20: ='BURNER STATUS'!J14 -> C | ... Q20: ='BURNER STATUS'!Q14 -> N | R20: =COUNTIF(C20:Q20,"O")+COUNTIF(C20:Q20,"B") -> 7 | S20: =COUNTIF(C20:Q20,"N")+COUNTIF(C20:Q20,"B") -> 4 | T20: =S20+R20 -> 11
B21: AIR REGISTER POSITION | C21: ='BURNER STATUS'!#REF! -> #REF! | D21: ='BURNER STATUS'!#REF! -> #REF! | E21: ='BURNER STATUS'!#REF! -> #REF! | F21: ='BURNER STATUS'!#REF! -> #REF! | G21: ='BURNER STATUS'!#REF! -> #REF! | H21: ='BURNER STATUS'!#REF! -> #REF! | I21: ='BURNER STATUS'!#REF! -> #REF! | J21: ='BURNER STATUS'!#REF! -> #REF! | ... Q21: ='BURNER STATUS'!#REF! -> #REF!
B22: ROW 2 | C22: ='BURNER STATUS'!C15 -> B | D22: ='BURNER STATUS'!D15 -> B | E22: ='BURNER STATUS'!E15 -> O | F22: ='BURNER STATUS'!F15 -> B | G22: ='BURNER STATUS'!G15 -> N | H22: ='BURNER STATUS'!H15 -> N | I22: ='BURNER STATUS'!I15 -> O | J22: ='BURNER STATUS'!J15 -> C | ... Q22: ='BURNER STATUS'!Q15 -> O | R22: =COUNTIF(C22:Q22,"O")+COUNTIF(C22:Q22,"B") -> 11 | S22: =COUNTIF(C22:Q22,"N")+COUNTIF(C22:Q22,"B") -> 9 | T22: =S22+R22 -> 20
B23: AIR REGISTER POSITION | C23: ='BURNER STATUS'!#REF! -> #REF! | D23: ='BURNER STATUS'!#REF! -> #REF! | E23: ='BURNER STATUS'!#REF! -> #REF! | F23: ='BURNER STATUS'!#REF! -> #REF! | G23: ='BURNER STATUS'!#REF! -> #REF! | H23: ='BURNER STATUS'!#REF! -> #REF! | I23: ='BURNER STATUS'!#REF! -> #REF! | J23: ='BURNER STATUS'!#REF! -> #REF! | ... Q23: ='BURNER STATUS'!#REF! -> #REF!
B24: ROW 3 | C24: ='BURNER STATUS'!C16 -> O | D24: ='BURNER STATUS'!D16 -> O | E24: ='BURNER STATUS'!E16 -> O | F24: ='BURNER STATUS'!F16 -> N | G24: ='BURNER STATUS'!G16 -> N | H24: ='BURNER STATUS'!H16 -> N | I24: ='BURNER STATUS'!I16 -> O | J24: ='BURNER STATUS'!J16 -> C | ... Q24: ='BURNER STATUS'!Q16 -> N | R24: =COUNTIF(C24:Q24,"O")+COUNTIF(C24:Q24,"B") -> 6 | S24: =COUNTIF(C24:Q24,"N")+COUNTIF(C24:Q24,"B") -> 7 | T24: =S24+R24 -> 13
B25: AIR REGISTER POSITION | C25: ='BURNER STATUS'!#REF! -> #REF! | D25: ='BURNER STATUS'!#REF! -> #REF! | E25: ='BURNER STATUS'!#REF! -> #REF! | F25: ='BURNER STATUS'!#REF! -> #REF! | G25: ='BURNER STATUS'!#REF! -> #REF! | H25: ='BURNER STATUS'!#REF! -> #REF! | I25: ='BURNER STATUS'!#REF! -> #REF! | J25: ='BURNER STATUS'!#REF! -> #REF! | ... Q25: ='BURNER STATUS'!#REF! -> #REF!
B26: ROW 4 | C26: ='BURNER STATUS'!C17 -> N | D26: ='BURNER STATUS'!D17 -> C | E26: ='BURNER STATUS'!E17 -> N | F26: ='BURNER STATUS'!F17 -> N | G26: ='BURNER STATUS'!G17 -> N | H26: ='BURNER STATUS'!H17 -> O | I26: ='BURNER STATUS'!I17 -> O | J26: ='BURNER STATUS'!J17 -> O | ... Q26: ='BURNER STATUS'!Q17 -> O | R26: =COUNTIF(C26:Q26,"O")+COUNTIF(C26:Q26,"B") -> 5 | S26: =COUNTIF(C26:Q26,"N")+COUNTIF(C26:Q26,"B") -> 8 | T26: =S26+R26 -> 13
B27: AIR REGISTER POSITION | C27: ='BURNER STATUS'!#REF! -> #REF! | D27: ='BURNER STATUS'!#REF! -> #REF! | E27: ='BURNER STATUS'!#REF! -> #REF! | F27: ='BURNER STATUS'!#REF! -> #REF! | G27: ='BURNER STATUS'!#REF! -> #REF! | H27: ='BURNER STATUS'!#REF! -> #REF! | I27: ='BURNER STATUS'!#REF! -> #REF! | J27: ='BURNER STATUS'!#REF! -> #REF! | ... Q27: ='BURNER STATUS'!#REF! -> #REF!
B28: ROW 5 | C28: ='BURNER STATUS'!C18 -> N | D28: ='BURNER STATUS'!D18 -> O | E28: ='BURNER STATUS'!E18 -> N | F28: ='BURNER STATUS'!F18 -> N | G28: ='BURNER STATUS'!G18 -> C | H28: ='BURNER STATUS'!H18 -> O | I28: ='BURNER STATUS'!I18 -> N | J28: ='BURNER STATUS'!J18 -> N | ... Q28: ='BURNER STATUS'!Q18 -> B | R28: =COUNTIF(C28:Q28,"O")+COUNTIF(C28:Q28,"B") -> 9 | S28: =COUNTIF(C28:Q28,"N")+COUNTIF(C28:Q28,"B") -> 12 | T28: =S28+R28 -> 21
B29: AIR REGISTER POSITION | C29: ='BURNER STATUS'!#REF! -> #REF! | D29: ='BURNER STATUS'!#REF! -> #REF! | E29: ='BURNER STATUS'!#REF! -> #REF! | F29: ='BURNER STATUS'!#REF! -> #REF! | G29: ='BURNER STATUS'!#REF! -> #REF! | H29: ='BURNER STATUS'!#REF! -> #REF! | I29: ='BURNER STATUS'!#REF! -> #REF! | J29: ='BURNER STATUS'!#REF! -> #REF! | ... Q29: ='BURNER STATUS'!#REF! -> #REF!
B30: ROW 6 | C30: ='BURNER STATUS'!C19 -> B | D30: ='BURNER STATUS'!D19 -> B | E30: ='BURNER STATUS'!E19 -> N | F30: ='BURNER STATUS'!F19 -> N | G30: ='BURNER STATUS'!G19 -> O | H30: ='BURNER STATUS'!H19 -> C | I30: ='BURNER STATUS'!I19 -> N | J30: ='BURNER STATUS'!J19 -> B | ... Q30: ='BURNER STATUS'!Q19 -> C | R30: =COUNTIF(C30:Q30,"O")+COUNTIF(C30:Q30,"B") -> 6 | S30: =COUNTIF(C30:Q30,"N")+COUNTIF(C30:Q30,"B") -> 11 | T30: =S30+R30 -> 17
B31: AIR REGISTER POSITION | C31: ='BURNER STATUS'!#REF! -> #REF! | D31: ='BURNER STATUS'!#REF! -> #REF! | E31: ='BURNER STATUS'!#REF! -> #REF! | F31: ='BURNER STATUS'!#REF! -> #REF! | G31: ='BURNER STATUS'!#REF! -> #REF! | H31: ='BURNER STATUS'!#REF! -> #REF! | I31: ='BURNER STATUS'!#REF! -> #REF! | J31: ='BURNER STATUS'!#REF! -> #REF! | ... Q31: ='BURNER STATUS'!#REF! -> #REF!
R32: =SUM(R20:R30) -> 44 | S32: =SUM(S20:S30) -> 51
C33: Reformer-C WALL | U33: CD total
B34: ROW 1 | C34: ='BURNER STATUS'!C22 -> C | D34: ='BURNER STATUS'!D22 -> C | E34: ='BURNER STATUS'!E22 -> N | F34: ='BURNER STATUS'!F22 -> C | G34: ='BURNER STATUS'!G22 -> C | H34: ='BURNER STATUS'!H22 -> C | I34: ='BURNER STATUS'!I22 -> C | J34: ='BURNER STATUS'!J22 -> C | ... Q34: ='BURNER STATUS'!Q22 -> C | R34: =COUNTIF(C34:Q34,"O")+COUNTIF(C34:Q34,"B") -> 0 | S34: =COUNTIF(C34:Q34,"N")+COUNTIF(C34:Q34,"B") -> 1 | T34: =S34+R34 -> 1 | U34: =T34+T48 -> 5 | W34: =-W6 -> -8 | X34: =-X6 -> -6 | Y34: =U34-U6 -> -14
B35: AIR REGISTER POSITION | C35: ='BURNER STATUS'!#REF! -> #REF! | D35: ='BURNER STATUS'!#REF! -> #REF! | E35: ='BURNER STATUS'!#REF! -> #REF! | F35: ='BURNER STATUS'!#REF! -> #REF! | G35: ='BURNER STATUS'!#REF! -> #REF! | H35: ='BURNER STATUS'!#REF! -> #REF! | I35: ='BURNER STATUS'!#REF! -> #REF! | J35: ='BURNER STATUS'!#REF! -> #REF! | ... Q35: ='BURNER STATUS'!#REF! -> #REF!
B36: ROW 2 | C36: ='BURNER STATUS'!C23 -> B | D36: ='BURNER STATUS'!D23 -> B | E36: ='BURNER STATUS'!E23 -> O | F36: ='BURNER STATUS'!F23 -> N | G36: ='BURNER STATUS'!G23 -> B | H36: ='BURNER STATUS'!H23 -> B | I36: ='BURNER STATUS'!I23 -> B | J36: ='BURNER STATUS'!J23 -> B | ... Q36: ='BURNER STATUS'!Q23 -> N | R36: =COUNTIF(C36:Q36,"O")+COUNTIF(C36:Q36,"B") -> 11 | S36: =COUNTIF(C36:Q36,"N")+COUNTIF(C36:Q36,"B") -> 14 | T36: =S36+R36 -> 25 | U36: =T36+T50 -> 50 | W36: =-W8 -> 2 | X36: =-X8 -> 13 | Y36: =U36-U8 -> 15
B37: AIR REGISTER POSITION | C37: ='BURNER STATUS'!#REF! -> #REF! | D37: ='BURNER STATUS'!#REF! -> #REF! | E37: ='BURNER STATUS'!#REF! -> #REF! | F37: ='BURNER STATUS'!#REF! -> #REF! | G37: ='BURNER STATUS'!#REF! -> #REF! | H37: ='BURNER STATUS'!#REF! -> #REF! | I37: ='BURNER STATUS'!#REF! -> #REF! | J37: ='BURNER STATUS'!#REF! -> #REF! | ... Q37: ='BURNER STATUS'!#REF! -> #REF!
B38: ROW 3 | C38: ='BURNER STATUS'!C24 -> B | D38: ='BURNER STATUS'!D24 -> B | E38: ='BURNER STATUS'!E24 -> O | F38: ='BURNER STATUS'!F24 -> B | G38: ='BURNER STATUS'!G24 -> O | H38: ='BURNER STATUS'!H24 -> O | I38: ='BURNER STATUS'!I24 -> O | J38: ='BURNER STATUS'!J24 -> B | ... Q38: ='BURNER STATUS'!Q24 -> B | R38: =COUNTIF(C38:Q38,"O")+COUNTIF(C38:Q38,"B") -> 14 | S38: =COUNTIF(C38:Q38,"N")+COUNTIF(C38:Q38,"B") -> 6 | T38: =S38+R38 -> 20 | U38: =T38+T52 -> 35 | W38: =-W10 -> 11 | X38: =-X10 -> -1 | Y38: =U38-U10 -> 10
B39: AIR REGISTER POSITION | C39: ='BURNER STATUS'!#REF! -> #REF! | D39: ='BURNER STATUS'!#REF! -> #REF! | E39: ='BURNER STATUS'!#REF! -> #REF! | F39: ='BURNER STATUS'!#REF! -> #REF! | G39: ='BURNER STATUS'!#REF! -> #REF! | H39: ='BURNER STATUS'!#REF! -> #REF! | I39: ='BURNER STATUS'!#REF! -> #REF! | J39: ='BURNER STATUS'!#REF! -> #REF! | ... Q39: ='BURNER STATUS'!#REF! -> #REF!
B40: ROW 4 | C40: ='BURNER STATUS'!C25 -> C | D40: ='BURNER STATUS'!D25 -> O | E40: ='BURNER STATUS'!E25 -> C | F40: ='BURNER STATUS'!F25 -> B | G40: ='BURNER STATUS'!G25 -> N | H40: ='BURNER STATUS'!H25 -> C | I40: ='BURNER STATUS'!I25 -> B | J40: ='BURNER STATUS'!J25 -> O | ... Q40: ='BURNER STATUS'!Q25 -> N | R40: =COUNTIF(C40:Q40,"O")+COUNTIF(C40:Q40,"B") -> 4 | S40: =COUNTIF(C40:Q40,"N")+COUNTIF(C40:Q40,"B") -> 7 | T40: =S40+R40 -> 11 | U40: =T40+T54 -> 19 | W40: =-W12 -> -1 | X40: =-X12 -> -4 | Y40: =U40-U12 -> -5
B41: AIR REGISTER POSITION | C41: ='BURNER STATUS'!#REF! -> #REF! | D41: ='BURNER STATUS'!#REF! -> #REF! | E41: ='BURNER STATUS'!#REF! -> #REF! | F41: ='BURNER STATUS'!#REF! -> #REF! | G41: ='BURNER STATUS'!#REF! -> #REF! | H41: ='BURNER STATUS'!#REF! -> #REF! | I41: ='BURNER STATUS'!#REF! -> #REF! | J41: ='BURNER STATUS'!#REF! -> #REF! | ... Q41: ='BURNER STATUS'!#REF! -> #REF!
B42: ROW 5 | C42: ='BURNER STATUS'!C26 -> B | D42: ='BURNER STATUS'!D26 -> B | E42: ='BURNER STATUS'!E26 -> B | F42: ='BURNER STATUS'!F26 -> B | G42: ='BURNER STATUS'!G26 -> B | H42: ='BURNER STATUS'!H26 -> B | I42: ='BURNER STATUS'!I26 -> C | J42: ='BURNER STATUS'!J26 -> O | ... Q42: ='BURNER STATUS'!Q26 -> B | R42: =COUNTIF(C42:Q42,"O")+COUNTIF(C42:Q42,"B") -> 14 | S42: =COUNTIF(C42:Q42,"N")+COUNTIF(C42:Q42,"B") -> 10 | T42: =S42+R42 -> 24 | U42: =T42+T56 -> 38 | W42: =-W14 -> 5 | X42: =-X14 -> -7 | Y42: =U42-U14 -> -2
B43: AIR REGISTER POSITION | C43: ='BURNER STATUS'!#REF! -> #REF! | D43: ='BURNER STATUS'!#REF! -> #REF! | E43: ='BURNER STATUS'!#REF! -> #REF! | F43: ='BURNER STATUS'!#REF! -> #REF! | G43: ='BURNER STATUS'!#REF! -> #REF! | H43: ='BURNER STATUS'!#REF! -> #REF! | I43: ='BURNER STATUS'!#REF! -> #REF! | J43: ='BURNER STATUS'!#REF! -> #REF! | ... Q43: ='BURNER STATUS'!#REF! -> #REF!
...
